<?xml version='1.0' encoding='ASCII'?>
<robot xmlns:xacro="http://wiki.ros.org/xacro">
  <xacro:macro name="HumanHand20DOF" params="prefix">
    <link name="${prefix}base_link"/>
    <joint name="${prefix}base_link_palm" type="fixed">
      <origin rpy="1.57079633 0.00000000 0.00000000"/>
      <parent link="${prefix}base_link"/>
      <child link="${prefix}palm"/>
    </joint>
    <link name="${prefix}palm">
      <visual>
        <geometry>
          <mesh filename="package://ros_thermal_grasp/data/HumanHand20DOF/palm.stl" scale="0.00100000 0.00100000 0.00100000"/>
        </geometry>
      </visual>
      <inertial>
        <mass value="0.15000000"/>
        <inertia ixx="3.3554e-07" ixy="2.3992e-08" ixz="5.0075e-08" iyy="1.0154e-06" iyz="-1.0785e-08" izz="8.5729e-07"/>
        <origin xyz="-0.08137586 0.00027660 -0.00027922"/>
      </inertial>
    </link>
    <link name="${prefix}index1">
      <visual>
        <geometry>
          <mesh filename="package://ros_thermal_grasp/data/HumanHand20DOF/index1.stl" scale="0.00100000 0.00100000 0.00100000"/>
        </geometry>
      </visual>
      <inertial>
        <mass value="0.15000000"/>
        <inertia ixx="2.5167e-09" ixy="3.3973e-10" ixz="-3.5973e-10" iyy="5.8923e-09" iyz="1.1618e-10" izz="6.1934e-09"/>
        <origin xyz="0.02011112 -0.00123457 0.00135728"/>
      </inertial>
    </link>
    <link name="${prefix}index1_0"/>
    <link name="${prefix}index2">
      <visual>
        <geometry>
          <mesh filename="package://ros_thermal_grasp/data/HumanHand20DOF/index2.stl" scale="0.00100000 0.00100000 0.00100000"/>
        </geometry>
      </visual>
      <inertial>
        <mass value="0.15000000"/>
        <inertia ixx="7.0013e-10" ixy="-6.2541e-11" ixz="-1.7946e-11" iyy="1.0301e-09" iyz="4.6358e-11" izz="1.0093e-09"/>
        <origin xyz="0.01323931 0.00108058 0.00078962"/>
      </inertial>
    </link>
    <link name="${prefix}index3">
      <visual>
        <geometry>
          <mesh filename="package://ros_thermal_grasp/data/HumanHand20DOF/index3.stl" scale="0.00100000 0.00100000 0.00100000"/>
        </geometry>
      </visual>
      <inertial>
        <mass value="0.15000000"/>
        <inertia ixx="2.8210e-10" ixy="-3.7642e-11" ixz="-4.5573e-11" iyy="5.1344e-10" iyz="9.9738e-13" izz="4.6923e-10"/>
        <origin xyz="0.01279242 -0.00009411 -0.00105114"/>
      </inertial>
    </link>
    <link name="${prefix}index1_0_fixed"/>
    <joint name="${prefix}palm_index1_0_fixed" type="revolute">
      <origin rpy="-1.57079633 0.00000000 0.00000000" xyz="-0.14005990 0.01120480 0.03641560"/>
      <parent link="${prefix}palm"/>
      <child link="${prefix}index1_0_fixed"/>
      <axis xyz="0.00000000 0.00000000 1.00000000"/>
      <limit effort="2.50000000" lower="-0.3490658503988659" upper="0.3490658503988659" velocity="0.52333333"/>
    </joint>
    <joint name="${prefix}index1_0_fixed_index1_0" type="fixed">
      <origin rpy="1.57079633 0.00000000 0.00000000" xyz="0.00000000 0.00000000 0.00000000"/>
      <parent link="${prefix}index1_0_fixed"/>
      <child link="${prefix}index1_0"/>
    </joint>
    <link name="${prefix}index1_fixed"/>
    <joint name="${prefix}index1_0_index1_fixed" type="revolute">
      <origin rpy="0.00000000 0.00000000 0.00000000" xyz="0.00000000 0.00000000 0.00000000"/>
      <parent link="${prefix}index1_0"/>
      <child link="${prefix}index1_fixed"/>
      <axis xyz="0.00000000 0.00000000 1.00000000"/>
      <limit effort="5.00000000" lower="-0.17453292519943295" upper="1.5707963267948966" velocity="0.52333333"/>
    </joint>
    <joint name="${prefix}index1_fixed_index1" type="fixed">
      <origin rpy="0.00000000 0.00000000 0.00000000" xyz="-0.04319000 0.00000000 0.00000000"/>
      <parent link="${prefix}index1_fixed"/>
      <child link="${prefix}index1"/>
    </joint>
    <link name="${prefix}index2_fixed"/>
    <joint name="${prefix}index1_index2_fixed" type="revolute">
      <origin rpy="0.00000000 0.00000000 0.00000000" xyz="0.00000000 0.00000000 0.00000000"/>
      <parent link="${prefix}index1"/>
      <child link="${prefix}index2_fixed"/>
      <axis xyz="0.00000000 0.00000000 1.00000000"/>
      <limit effort="5.00000000" lower="-0.17453292519943295" upper="1.5707963267948966" velocity="0.52333333"/>
    </joint>
    <joint name="${prefix}index2_fixed_index2" type="fixed">
      <origin rpy="0.00000000 0.00000000 0.00000000" xyz="-0.02956000 0.00000000 0.00000000"/>
      <parent link="${prefix}index2_fixed"/>
      <child link="${prefix}index2"/>
    </joint>
    <link name="${prefix}index3_fixed"/>
    <joint name="${prefix}index2_index3_fixed" type="revolute">
      <origin rpy="0.00000000 0.00000000 0.00000000" xyz="0.00000000 0.00000000 0.00000000"/>
      <parent link="${prefix}index2"/>
      <child link="${prefix}index3_fixed"/>
      <axis xyz="0.00000000 0.00000000 1.00000000"/>
      <limit effort="5.00000000" lower="-0.17453292519943295" upper="1.5707963267948966" velocity="0.52333333"/>
    </joint>
    <joint name="${prefix}index3_fixed_index3" type="fixed">
      <origin rpy="0.00000000 0.00000000 0.00000000" xyz="-0.02535000 0.00000000 0.00000000"/>
      <parent link="${prefix}index3_fixed"/>
      <child link="${prefix}index3"/>
    </joint>
    <link name="${prefix}mid1">
      <visual>
        <geometry>
          <mesh filename="package://ros_thermal_grasp/data/HumanHand20DOF/mid1.stl" scale="0.00100000 0.00100000 0.00100000"/>
        </geometry>
      </visual>
      <inertial>
        <mass value="0.15000000"/>
        <inertia ixx="2.4872e-09" ixy="-1.2104e-10" ixz="1.8077e-10" iyy="6.5822e-09" iyz="-2.0186e-11" izz="6.8252e-09"/>
        <origin xyz="0.02303335 0.00111214 -0.00040002"/>
      </inertial>
    </link>
    <link name="${prefix}mid1_0"/>
    <link name="${prefix}mid2">
      <visual>
        <geometry>
          <mesh filename="package://ros_thermal_grasp/data/HumanHand20DOF/mid2.stl" scale="0.00100000 0.00100000 0.00100000"/>
        </geometry>
      </visual>
      <inertial>
        <mass value="0.15000000"/>
        <inertia ixx="5.7452e-10" ixy="-6.2291e-11" ixz="-7.8131e-12" iyy="1.0540e-09" iyz="-1.3211e-12" izz="9.8236e-10"/>
        <origin xyz="0.01424607 0.00116390 -0.00075067"/>
      </inertial>
    </link>
    <link name="${prefix}mid3">
      <visual>
        <geometry>
          <mesh filename="package://ros_thermal_grasp/data/HumanHand20DOF/mid3.stl" scale="0.00100000 0.00100000 0.00100000"/>
        </geometry>
      </visual>
      <inertial>
        <mass value="0.15000000"/>
        <inertia ixx="2.2519e-10" ixy="-2.7224e-11" ixz="-1.8756e-11" iyy="4.3349e-10" iyz="-1.0208e-11" izz="3.9091e-10"/>
        <origin xyz="0.01619712 0.00013602 -0.00123824"/>
      </inertial>
    </link>
    <link name="${prefix}mid1_0_fixed"/>
    <joint name="${prefix}palm_mid1_0_fixed" type="revolute">
      <origin rpy="-1.57079633 0.00000000 0.00000000" xyz="-0.14566230 0.01120480 0.00840360"/>
      <parent link="${prefix}palm"/>
      <child link="${prefix}mid1_0_fixed"/>
      <axis xyz="0.00000000 0.00000000 1.00000000"/>
      <limit effort="5.00000000" lower="-0.17453292519943295" upper="0.17453292519943295" velocity="0.52333333"/>
    </joint>
    <joint name="${prefix}mid1_0_fixed_mid1_0" type="fixed">
      <origin rpy="1.57079633 0.00000000 0.00000000" xyz="0.00000000 0.00000000 0.00000000"/>
      <parent link="${prefix}mid1_0_fixed"/>
      <child link="${prefix}mid1_0"/>
    </joint>
    <link name="${prefix}mid1_fixed"/>
    <joint name="${prefix}mid1_0_mid1_fixed" type="revolute">
      <origin rpy="0.00000000 0.00000000 0.00000000" xyz="0.00000000 0.00000000 0.00000000"/>
      <parent link="${prefix}mid1_0"/>
      <child link="${prefix}mid1_fixed"/>
      <axis xyz="0.00000000 0.00000000 1.00000000"/>
      <limit effort="2.50000000" lower="-0.17453292519943295" upper="1.5707963267948966" velocity="0.52333333"/>
    </joint>
    <joint name="${prefix}mid1_fixed_mid1" type="fixed">
      <origin rpy="0.00000000 0.00000000 0.00000000" xyz="-0.04620000 0.00000000 0.00000000"/>
      <parent link="${prefix}mid1_fixed"/>
      <child link="${prefix}mid1"/>
    </joint>
    <link name="${prefix}mid2_fixed"/>
    <joint name="${prefix}mid1_mid2_fixed" type="revolute">
      <origin rpy="0.00000000 0.00000000 0.00000000" xyz="0.00000000 0.00000000 0.00000000"/>
      <parent link="${prefix}mid1"/>
      <child link="${prefix}mid2_fixed"/>
      <axis xyz="0.00000000 0.00000000 1.00000000"/>
      <limit effort="5.00000000" lower="-0.17453292519943295" upper="1.5707963267948966" velocity="0.52333333"/>
    </joint>
    <joint name="${prefix}mid2_fixed_mid2" type="fixed">
      <origin rpy="0.00000000 0.00000000 0.00000000" xyz="-0.03099000 0.00000000 0.00000000"/>
      <parent link="${prefix}mid2_fixed"/>
      <child link="${prefix}mid2"/>
    </joint>
    <link name="${prefix}mid3_fixed"/>
    <joint name="${prefix}mid2_mid3_fixed" type="revolute">
      <origin rpy="0.00000000 0.00000000 0.00000000" xyz="0.00000000 0.00000000 0.00000000"/>
      <parent link="${prefix}mid2"/>
      <child link="${prefix}mid3_fixed"/>
      <axis xyz="0.00000000 0.00000000 1.00000000"/>
      <limit effort="5.00000000" lower="-0.17453292519943295" upper="1.5707963267948966" velocity="0.52333333"/>
    </joint>
    <joint name="${prefix}mid3_fixed_mid3" type="fixed">
      <origin rpy="0.00000000 0.00000000 0.00000000" xyz="-0.02920000 0.00000000 0.00000000"/>
      <parent link="${prefix}mid3_fixed"/>
      <child link="${prefix}mid3"/>
    </joint>
    <link name="${prefix}ring1">
      <visual>
        <geometry>
          <mesh filename="package://ros_thermal_grasp/data/HumanHand20DOF/ring1.stl" scale="0.00100000 0.00100000 0.00100000"/>
        </geometry>
      </visual>
      <inertial>
        <mass value="0.15000000"/>
        <inertia ixx="1.7522e-09" ixy="9.4905e-11" ixz="5.0620e-11" iyy="4.7666e-09" iyz="8.8841e-11" izz="5.1380e-09"/>
        <origin xyz="0.02304180 0.00157391 0.00013144"/>
      </inertial>
    </link>
    <link name="${prefix}ring1_0"/>
    <link name="${prefix}ring2">
      <visual>
        <geometry>
          <mesh filename="package://ros_thermal_grasp/data/HumanHand20DOF/ring2.stl" scale="0.00100000 0.00100000 0.00100000"/>
        </geometry>
      </visual>
      <inertial>
        <mass value="0.15000000"/>
        <inertia ixx="4.5378e-10" ixy="-9.9898e-11" ixz="-2.8513e-11" iyy="7.8196e-10" iyz="-3.1049e-11" izz="7.5320e-10"/>
        <origin xyz="0.01610605 0.00034652 -0.00137162"/>
      </inertial>
    </link>
    <link name="${prefix}ring3">
      <visual>
        <geometry>
          <mesh filename="package://ros_thermal_grasp/data/HumanHand20DOF/ring3.stl" scale="0.00100000 0.00100000 0.00100000"/>
        </geometry>
      </visual>
      <inertial>
        <mass value="0.15000000"/>
        <inertia ixx="1.9218e-10" ixy="-1.2536e-11" ixz="7.8242e-12" iyy="-1.2536e-11" iyz="4.2733e-10" izz="-1.4502e-11"/>
        <origin xyz="0.01407043 -0.00211063 -0.00254810"/>
      </inertial>
    </link>
    <link name="${prefix}ring1_0_fixed"/>
    <joint name="${prefix}palm_ring1_0_fixed" type="revolute">
      <origin rpy="-1.57079633 0.00000000 0.00000000" xyz="-0.14566230 0.00560250 -0.01960840"/>
      <parent link="${prefix}palm"/>
      <child link="${prefix}ring1_0_fixed"/>
      <axis xyz="0.00000000 0.00000000 1.00000000"/>
      <limit effort="5.00000000" lower="-0.3490658503988659" upper="0.3490658503988659" velocity="0.52333333"/>
    </joint>
    <joint name="${prefix}ring1_0_fixed_ring1_0" type="fixed">
      <origin rpy="1.57079633 0.00000000 0.00000000" xyz="0.00000000 0.00000000 0.00000000"/>
      <parent link="${prefix}ring1_0_fixed"/>
      <child link="${prefix}ring1_0"/>
    </joint>
    <link name="${prefix}ring1_fixed"/>
    <joint name="${prefix}ring1_0_ring1_fixed" type="revolute">
      <origin rpy="0.00000000 0.00000000 0.00000000" xyz="0.00000000 0.00000000 0.00000000"/>
      <parent link="${prefix}ring1_0"/>
      <child link="${prefix}ring1_fixed"/>
      <axis xyz="0.00000000 0.00000000 1.00000000"/>
      <limit effort="2.50000000" lower="-0.17453292519943295" upper="1.5707963267948966" velocity="0.52333333"/>
    </joint>
    <joint name="${prefix}ring1_fixed_ring1" type="fixed">
      <origin rpy="0.00000000 0.00000000 0.00000000" xyz="-0.03912000 0.00000000 0.00000000"/>
      <parent link="${prefix}ring1_fixed"/>
      <child link="${prefix}ring1"/>
    </joint>
    <link name="${prefix}ring2_fixed"/>
    <joint name="${prefix}ring1_ring2_fixed" type="revolute">
      <origin rpy="0.00000000 0.00000000 0.00000000" xyz="0.00000000 0.00000000 0.00000000"/>
      <parent link="${prefix}ring1"/>
      <child link="${prefix}ring2_fixed"/>
      <axis xyz="0.00000000 0.00000000 1.00000000"/>
      <limit effort="5.00000000" lower="-0.17453292519943295" upper="1.5707963267948966" velocity="0.52333333"/>
    </joint>
    <joint name="${prefix}ring2_fixed_ring2" type="fixed">
      <origin rpy="0.00000000 0.00000000 0.00000000" xyz="-0.02831000 0.00000000 0.00000000"/>
      <parent link="${prefix}ring2_fixed"/>
      <child link="${prefix}ring2"/>
    </joint>
    <link name="${prefix}ring3_fixed"/>
    <joint name="${prefix}ring2_ring3_fixed" type="revolute">
      <origin rpy="0.00000000 0.00000000 0.00000000" xyz="0.00000000 0.00000000 0.00000000"/>
      <parent link="${prefix}ring2"/>
      <child link="${prefix}ring3_fixed"/>
      <axis xyz="0.00000000 0.00000000 1.00000000"/>
      <limit effort="5.00000000" lower="-0.17453292519943295" upper="1.5707963267948966" velocity="0.52333333"/>
    </joint>
    <joint name="${prefix}ring3_fixed_ring3" type="fixed">
      <origin rpy="0.00000000 0.00000000 0.00000000" xyz="-0.02448000 0.00000000 0.00000000"/>
      <parent link="${prefix}ring3_fixed"/>
      <child link="${prefix}ring3"/>
    </joint>
    <link name="${prefix}pinky1">
      <visual>
        <geometry>
          <mesh filename="package://ros_thermal_grasp/data/HumanHand20DOF/pinky1.stl" scale="0.00100000 0.00100000 0.00100000"/>
        </geometry>
      </visual>
      <inertial>
        <mass value="0.15000000"/>
        <inertia ixx="9.1748e-10" ixy="1.9553e-10" ixz="-9.7358e-12" iyy="1.6568e-09" iyz="8.1955e-11" izz="1.8240e-09"/>
        <origin xyz="0.01815957 0.00125307 0.00044100"/>
      </inertial>
    </link>
    <link name="${prefix}pinky1_0"/>
    <link name="${prefix}pinky2">
      <visual>
        <geometry>
          <mesh filename="package://ros_thermal_grasp/data/HumanHand20DOF/pinky2.stl" scale="0.00100000 0.00100000 0.00100000"/>
        </geometry>
      </visual>
      <inertial>
        <mass value="0.15000000"/>
        <inertia ixx="2.3418e-10" ixy="2.6896e-12" ixz="1.9487e-11" iyy="3.6013e-10" iyz="-2.2696e-13" izz="3.5602e-10"/>
        <origin xyz="0.01160125 0.00007157 -0.00141618"/>
      </inertial>
    </link>
    <link name="${prefix}pinky3">
      <visual>
        <geometry>
          <mesh filename="package://ros_thermal_grasp/data/HumanHand20DOF/pinky3.stl" scale="0.00100000 0.00100000 0.00100000"/>
        </geometry>
      </visual>
      <inertial>
        <mass value="0.15000000"/>
        <inertia ixx="1.5031e-10" ixy="-1.7414e-11" ixz="2.7273e-11" iyy="3.1403e-10" iyz="2.1438e-12" izz="2.1438e-12"/>
        <origin xyz="0.01421079 -0.00252850 -0.00003521"/>
      </inertial>
    </link>
    <link name="${prefix}pinky1_0_fixed"/>
    <joint name="${prefix}palm_pinky1_0_fixed" type="revolute">
      <origin rpy="-1.57079633 0.00000000 0.00000000" xyz="-0.13445750 -0.00840350 -0.04201800"/>
      <parent link="${prefix}palm"/>
      <child link="${prefix}pinky1_0_fixed"/>
      <axis xyz="0.00000000 0.00000000 1.00000000"/>
      <limit effort="5.00000000" lower="-0.5235987755982988" upper="0.5235987755982988" velocity="0.52333333"/>
    </joint>
    <joint name="${prefix}pinky1_0_fixed_pinky1_0" type="fixed">
      <origin rpy="1.57079633 0.00000000 0.00000000" xyz="0.00000000 0.00000000 0.00000000"/>
      <parent link="${prefix}pinky1_0_fixed"/>
      <child link="${prefix}pinky1_0"/>
    </joint>
    <link name="${prefix}pinky1_fixed"/>
    <joint name="${prefix}pinky1_0_pinky1_fixed" type="revolute">
      <origin rpy="0.00000000 0.00000000 0.00000000" xyz="0.00000000 0.00000000 0.00000000"/>
      <parent link="${prefix}pinky1_0"/>
      <child link="${prefix}pinky1_fixed"/>
      <axis xyz="0.00000000 0.00000000 1.00000000"/>
      <limit effort="2.50000000" lower="-0.17453292519943295" upper="1.5707963267948966" velocity="0.52333333"/>
    </joint>
    <joint name="${prefix}pinky1_fixed_pinky1" type="fixed">
      <origin rpy="0.00000000 0.00000000 0.00000000" xyz="-0.02991000 0.00000000 0.00000000"/>
      <parent link="${prefix}pinky1_fixed"/>
      <child link="${prefix}pinky1"/>
    </joint>
    <link name="${prefix}pinky2_fixed"/>
    <joint name="${prefix}pinky1_pinky2_fixed" type="revolute">
      <origin rpy="0.00000000 0.00000000 0.00000000" xyz="0.00000000 0.00000000 0.00000000"/>
      <parent link="${prefix}pinky1"/>
      <child link="${prefix}pinky2_fixed"/>
      <axis xyz="0.00000000 0.00000000 1.00000000"/>
      <limit effort="5.00000000" lower="-0.17453292519943295" upper="1.5707963267948966" velocity="0.52333333"/>
    </joint>
    <joint name="${prefix}pinky2_fixed_pinky2" type="fixed">
      <origin rpy="0.00000000 0.00000000 0.00000000" xyz="-0.02110000 0.00000000 0.00000000"/>
      <parent link="${prefix}pinky2_fixed"/>
      <child link="${prefix}pinky2"/>
    </joint>
    <link name="${prefix}pinky3_fixed"/>
    <joint name="${prefix}pinky2_pinky3_fixed" type="revolute">
      <origin rpy="0.00000000 0.00000000 0.00000000" xyz="0.00000000 0.00000000 0.00000000"/>
      <parent link="${prefix}pinky2"/>
      <child link="${prefix}pinky3_fixed"/>
      <axis xyz="0.00000000 0.00000000 1.00000000"/>
      <limit effort="5.00000000" lower="-0.17453292519943295" upper="1.5707963267948966" velocity="0.52333333"/>
    </joint>
    <joint name="${prefix}pinky3_fixed_pinky3" type="fixed">
      <origin rpy="0.00000000 0.00000000 0.00000000" xyz="-0.02316000 0.00000000 0.00000000"/>
      <parent link="${prefix}pinky3_fixed"/>
      <child link="${prefix}pinky3"/>
    </joint>
    <link name="${prefix}thumb1">
      <visual>
        <geometry>
          <mesh filename="package://ros_thermal_grasp/data/HumanHand20DOF/thumb1.stl" scale="0.00100000 0.00100000 0.00100000"/>
        </geometry>
      </visual>
      <inertial>
        <mass value="0.15000000"/>
        <inertia ixx="1.4027e-08" ixy="-5.0407e-09" ixz="2.0608e-09" iyy="2.8099e-08" iyz="-3.4404e-10" izz="2.7290e-08"/>
        <origin xyz="-0.01284141 0.00304866 -0.00010647"/>
      </inertial>
    </link>
    <link name="${prefix}thumb1_0"/>
    <link name="${prefix}thumb2">
      <visual>
        <geometry>
          <mesh filename="package://ros_thermal_grasp/data/HumanHand20DOF/thumb2.stl" scale="0.00100000 0.00100000 0.00100000"/>
        </geometry>
      </visual>
      <inertial>
        <mass value="0.15000000"/>
        <inertia ixx="1.2243e-09" ixy="-2.6135e-10" ixz="3.8755e-11" iyy="2.3447e-09" iyz="7.2414e-11" izz="2.2779e-09"/>
        <origin xyz="-0.01259928 -0.00318035 0.00054580"/>
      </inertial>
    </link>
    <link name="${prefix}thumb3">
      <visual>
        <geometry>
          <mesh filename="package://ros_thermal_grasp/data/HumanHand20DOF/thumb3.stl" scale="0.00100000 0.00100000 0.00100000"/>
        </geometry>
      </visual>
      <inertial>
        <mass value="0.15000000"/>
        <inertia ixx="9.5483e-10" ixy="4.0583e-11" ixz="3.4110e-11" iyy="8.2473e-10" iyz="-1.9831e-11" izz="5.3116e-10"/>
        <origin xyz="0.00097733 0.00245070 0.01787106"/>
      </inertial>
    </link>
    <link name="${prefix}thumb1_0_fixed"/>
    <joint name="${prefix}palm_thumb1_0_fixed" type="revolute">
      <origin rpy="1.36529812 -0.42128841 -1.73437755" xyz="-0.05062410 -0.01150820 0.01893170"/>
      <parent link="${prefix}palm"/>
      <child link="${prefix}thumb1_0_fixed"/>
      <axis xyz="0.00000000 0.00000000 1.00000000"/>
      <limit effort="5.00000000" lower="-1.3962634015954636" upper="1.2217304763960306" velocity="0.52333333"/>
    </joint>
    <joint name="${prefix}thumb1_0_fixed_thumb1_0" type="fixed">
      <origin rpy="1.57079633 0.00000000 0.00000000" xyz="0.00000000 0.00000000 0.00000000"/>
      <parent link="${prefix}thumb1_0_fixed"/>
      <child link="${prefix}thumb1_0"/>
    </joint>
    <link name="${prefix}thumb1_fixed"/>
    <joint name="${prefix}thumb1_0_thumb1_fixed" type="revolute">
      <origin rpy="0.00000000 0.00000000 0.00000000" xyz="0.00000000 0.00000000 0.00000000"/>
      <parent link="${prefix}thumb1_0"/>
      <child link="${prefix}thumb1_fixed"/>
      <axis xyz="0.00000000 0.00000000 1.00000000"/>
      <limit effort="5.00000000" lower="-0.8726646259971648" upper="0.4363323129985824" velocity="0.52333333"/>
    </joint>
    <link name="${prefix}thumb1_dh"/>
    <joint name="${prefix}thumb1_fixed_thumb1_dh" type="fixed">
      <origin rpy="0.00000000 0.00000000 0.86393798"/>
      <parent link="${prefix}thumb1_fixed"/>
      <child link="${prefix}thumb1_dh"/>
    </joint>
    <joint name="${prefix}thumb1_dh_thumb1" type="fixed">
      <origin rpy="0.76794487 0.00000000 0.00000000" xyz="0.05211930 0.00000000 0.00000000"/>
      <parent link="${prefix}thumb1_dh"/>
      <child link="${prefix}thumb1"/>
    </joint>
    <link name="${prefix}thumb2_fixed"/>
    <joint name="${prefix}thumb1_thumb2_fixed" type="revolute">
      <origin rpy="0.00000000 0.00000000 0.00000000" xyz="0.00000000 0.00000000 0.00000000"/>
      <parent link="${prefix}thumb1"/>
      <child link="${prefix}thumb2_fixed"/>
      <axis xyz="0.00000000 0.00000000 1.00000000"/>
      <limit effort="5.00000000" lower="0.0" upper="1.5707963267948966" velocity="0.52333333"/>
    </joint>
    <link name="${prefix}thumb2_dh"/>
    <joint name="${prefix}thumb2_fixed_thumb2_dh" type="fixed">
      <origin rpy="0.00000000 0.00000000 0.08726646"/>
      <parent link="${prefix}thumb2_fixed"/>
      <child link="${prefix}thumb2_dh"/>
    </joint>
    <joint name="${prefix}thumb2_dh_thumb2" type="fixed">
      <origin rpy="0.00000000 0.00000000 0.00000000" xyz="0.04076380 0.00000000 0.00000000"/>
      <parent link="${prefix}thumb2_dh"/>
      <child link="${prefix}thumb2"/>
    </joint>
    <link name="${prefix}thumb3_fixed"/>
    <joint name="${prefix}thumb2_thumb3_fixed" type="revolute">
      <origin rpy="0.00000000 0.00000000 0.00000000" xyz="0.00000000 0.00000000 0.00000000"/>
      <parent link="${prefix}thumb2"/>
      <child link="${prefix}thumb3_fixed"/>
      <axis xyz="0.00000000 0.00000000 1.00000000"/>
      <limit effort="5.00000000" lower="0.0" upper="1.7453292519943295" velocity="0.52333333"/>
    </joint>
    <link name="${prefix}thumb3_dh"/>
    <joint name="${prefix}thumb3_fixed_thumb3_dh" type="fixed">
      <origin rpy="0.00000000 0.00000000 1.48352986"/>
      <parent link="${prefix}thumb3_fixed"/>
      <child link="${prefix}thumb3_dh"/>
    </joint>
    <joint name="${prefix}thumb3_dh_thumb3" type="fixed">
      <origin rpy="1.57079633 0.00000000 0.00000000" xyz="0.00000000 0.00000000 0.00000000"/>
      <parent link="${prefix}thumb3_dh"/>
      <child link="${prefix}thumb3"/>
    </joint>
  </xacro:macro>
</robot>
