<?xml version="1.0" ?>
<!-- =================================================================================== -->
<!-- |    This document was autogenerated by xacro from ThermalRobot.xacro             | -->
<!-- |    EDITING THIS FILE BY HAND IS NOT RECOMMENDED                                 | -->
<!-- =================================================================================== -->
<robot name="ThermalRobot" xmlns:xacro="http://wiki.ros.org/xacro">
  <!-- link list -->
  <link name="robot_base_link">
    <visual>
      <origin rpy="0 0 0" xyz="0 0 0"/>
      <geometry>
        <mesh filename="package://kuka_lbr_iiwa_support/meshes/lbr_iiwa_14_r820/visual/base_link.dae"/>
      </geometry>
    </visual>
    <collision>
      <origin rpy="0 0 0" xyz="0 0 0"/>
      <geometry>
        <mesh filename="package://kuka_lbr_iiwa_support/meshes/lbr_iiwa_14_r820/collision/base_link.stl"/>
      </geometry>
    </collision>
  </link>
  <link name="robot_link_1">
    <visual>
      <origin rpy="0 0 0" xyz="0 0 0"/>
      <geometry>
        <mesh filename="package://kuka_lbr_iiwa_support/meshes/lbr_iiwa_14_r820/visual/link_1.dae"/>
      </geometry>
    </visual>
    <collision>
      <origin rpy="0 0 0" xyz="0 0 0"/>
      <geometry>
        <mesh filename="package://kuka_lbr_iiwa_support/meshes/lbr_iiwa_14_r820/collision/link_1.stl"/>
      </geometry>
    </collision>
  </link>
  <link name="robot_link_2">
    <visual>
      <origin rpy="0 0 0" xyz="0 0 0"/>
      <geometry>
        <mesh filename="package://kuka_lbr_iiwa_support/meshes/lbr_iiwa_14_r820/visual/link_2.dae"/>
      </geometry>
    </visual>
    <collision>
      <origin rpy="0 0 0" xyz="0 0 0"/>
      <geometry>
        <mesh filename="package://kuka_lbr_iiwa_support/meshes/lbr_iiwa_14_r820/collision/link_2.stl"/>
      </geometry>
    </collision>
  </link>
  <link name="robot_link_3">
    <visual>
      <origin rpy="0 0 0" xyz="0 0 0"/>
      <geometry>
        <mesh filename="package://kuka_lbr_iiwa_support/meshes/lbr_iiwa_14_r820/visual/link_3.dae"/>
      </geometry>
    </visual>
    <collision>
      <origin rpy="0 0 0" xyz="0 0 0"/>
      <geometry>
        <mesh filename="package://kuka_lbr_iiwa_support/meshes/lbr_iiwa_14_r820/collision/link_3.stl"/>
      </geometry>
    </collision>
  </link>
  <link name="robot_link_4">
    <visual>
      <origin rpy="0 0 0" xyz="0 0 0"/>
      <geometry>
        <mesh filename="package://kuka_lbr_iiwa_support/meshes/lbr_iiwa_14_r820/visual/link_4.dae"/>
      </geometry>
    </visual>
    <collision>
      <origin rpy="0 0 0" xyz="0 0 0"/>
      <geometry>
        <mesh filename="package://kuka_lbr_iiwa_support/meshes/lbr_iiwa_14_r820/collision/link_4.stl"/>
      </geometry>
    </collision>
  </link>
  <link name="robot_link_5">
    <visual>
      <origin rpy="0 0 0" xyz="0 0 0"/>
      <geometry>
        <mesh filename="package://kuka_lbr_iiwa_support/meshes/lbr_iiwa_14_r820/visual/link_5.dae"/>
      </geometry>
    </visual>
    <collision>
      <origin rpy="0 0 0" xyz="0 0 0"/>
      <geometry>
        <mesh filename="package://kuka_lbr_iiwa_support/meshes/lbr_iiwa_14_r820/collision/link_5.stl"/>
      </geometry>
    </collision>
  </link>
  <link name="robot_link_6">
    <visual>
      <origin rpy="0 0 0" xyz="0 0 0"/>
      <geometry>
        <mesh filename="package://kuka_lbr_iiwa_support/meshes/lbr_iiwa_14_r820/visual/link_6.dae"/>
      </geometry>
    </visual>
    <collision>
      <origin rpy="0 0 0" xyz="0 0 0"/>
      <geometry>
        <mesh filename="package://kuka_lbr_iiwa_support/meshes/lbr_iiwa_14_r820/collision/link_6.stl"/>
      </geometry>
    </collision>
  </link>
  <link name="robot_link_7">
    <visual>
      <origin rpy="0 0 0" xyz="0 0 0"/>
      <geometry>
        <mesh filename="package://kuka_lbr_iiwa_support/meshes/lbr_iiwa_14_r820/visual/link_7.dae"/>
      </geometry>
    </visual>
    <collision>
      <origin rpy="0 0 0" xyz="0 0 0"/>
      <geometry>
        <mesh filename="package://kuka_lbr_iiwa_support/meshes/lbr_iiwa_14_r820/collision/link_7.stl"/>
      </geometry>
    </collision>
  </link>
  <link name="robot_tool0"/>
  <!-- end of link list -->
  <!-- joint list -->
  <joint name="robot_joint_a1" type="revolute">
    <origin rpy="0 0 0" xyz="0 0 0"/>
    <parent link="robot_base_link"/>
    <child link="robot_link_1"/>
    <axis xyz="0 0 1"/>
    <limit effort="0" lower="-2.9668" upper="2.9668" velocity="1.4834"/>
  </joint>
  <joint name="robot_joint_a2" type="revolute">
    <origin rpy="0 0 0" xyz="-0.00043624 0 0.36"/>
    <parent link="robot_link_1"/>
    <child link="robot_link_2"/>
    <axis xyz="0 1 0"/>
    <limit effort="0" lower="-2.0942" upper="2.0942" velocity="1.4834"/>
  </joint>
  <joint name="robot_joint_a3" type="revolute">
    <origin rpy="0 0 0" xyz="0 0 0"/>
    <parent link="robot_link_2"/>
    <child link="robot_link_3"/>
    <axis xyz="0 0 1"/>
    <limit effort="0" lower="-2.9668" upper="2.9668" velocity="1.7452"/>
  </joint>
  <joint name="robot_joint_a4" type="revolute">
    <origin rpy="0 0 0" xyz="0.00043624 0 0.42"/>
    <parent link="robot_link_3"/>
    <child link="robot_link_4"/>
    <axis xyz="0 -1 0"/>
    <limit effort="0" lower="-2.0942" upper="2.0942" velocity="1.3089"/>
  </joint>
  <joint name="robot_joint_a5" type="revolute">
    <origin rpy="0 0 0" xyz="0 0 0"/>
    <parent link="robot_link_4"/>
    <child link="robot_link_5"/>
    <axis xyz="0 0 1"/>
    <limit effort="0" lower="-2.9668" upper="2.9668" velocity="2.2688"/>
  </joint>
  <joint name="robot_joint_a6" type="revolute">
    <origin rpy="0 0 0" xyz="0 0 0.4"/>
    <parent link="robot_link_5"/>
    <child link="robot_link_6"/>
    <axis xyz="0 1 0"/>
    <limit effort="0" lower="-2.0942" upper="2.0942" velocity="2.356"/>
  </joint>
  <joint name="robot_joint_a7" type="revolute">
    <origin rpy="0 0 0" xyz="0 0 0"/>
    <parent link="robot_link_6"/>
    <child link="robot_link_7"/>
    <axis xyz="0 0 1"/>
    <limit effort="0" lower="-3.0541" upper="3.0541" velocity="2.356"/>
  </joint>
  <joint name="robot_joint_a7-tool0" type="fixed">
    <origin rpy="0 0 0" xyz="0 0 0.126"/>
    <parent link="robot_link_7"/>
    <child link="robot_tool0"/>
    <axis xyz="0 0 0"/>
  </joint>
  <!-- end of joint list -->
  <!-- ROS base_link to KUKA $ROBROOT coordinate system transform -->
  <link name="robot_base"/>
  <joint name="robot_base_link-base" type="fixed">
    <origin rpy="0 0 0" xyz="0 0 0"/>
    <parent link="robot_base_link"/>
    <child link="robot_base"/>
  </joint>
  <!-- ======================== BASE PARAMS ========================= -->
  <!-- ======================== FINGER PARAMS ======================== -->
  <!-- full height from joint to tip. when used,
         the radius of the finger tip sphere will be subtracted
         and one fixed link will be added for the tip. -->
  <!-- ========================= THUMB PARAMS ========================= -->
  <!-- ========================= LIMITS ========================= -->
  <!-- ============================================================================= -->
  <!-- BASE -->
  <material name="Black">
    <color rgba="0.2 0.2 0.2 1"/>
  </material>
  <material name="Grey">
    <color rgba="0.2 0.2 0.2 1"/>
  </material>
  <material name="White">
    <color rgba="1 1 1 1"/>
  </material>
  <!--link name="${prefix}allegro_mount">
      <inertial>
        <mass value="0.05" />
        <origin xyz="0 0 0" rpy="0 0 0" />
        <inertia ixx="1e-4" ixy="0" ixz="0" iyy="1e-4" iyz="0" izz="1e-4" />
      </inertial>
      <visual>
        <origin xyz="-0.0425 -0.0425 0" rpy="0 0 0" />
        <geometry>
          <mesh filename="package://ros_thermal_grasp/data/allegro/allegro_mount.stl" />
        </geometry>
        <material name="LBR4_Grey" />
      </visual>
      <collision>
        <origin xyz="-0.0425 -0.0425 0" rpy="0 0 0" />
        <geometry>
          <mesh filename="package://ros_thermal_grasp/data/allegro/allegro_mount.stl" />
        </geometry>
      </collision>
    </link-->
  <!--joint name="${prefix}allegro_mount_joint" type="fixed">
      <origin xyz="0.065 0 0.0275" rpy="0 1.57 0" />
      <parent link="${prefix}allegro_mount" />
      <child link="${prefix}palm_link" />
    </joint-->
  <link name="hand_palm_link">
    <inertial>
      <mass value="0.4154"/>
      <origin rpy="0 0 0" xyz="0 0 0"/>
      <inertia ixx="1e-4" ixy="0" ixz="0" iyy="1e-4" iyz="0" izz="1e-4"/>
    </inertial>
    <visual>
      <geometry>
        <mesh filename="package://ros_thermal_grasp/data/allegro/base_link.STL"/>
      </geometry>
      <origin rpy="0 0 0" xyz="0 0 0 "/>
      <material name="Black"/>
    </visual>
    <collision>
      <origin rpy="0 0 0" xyz="-0.009300 0 -0.0475"/>
      <geometry>
        <box size="0.0408 0.1130 0.095"/>
      </geometry>
    </collision>
  </link>
  <gazebo reference="palm_link">
    <material value="Gazebo/Black"/>
  </gazebo>
  <!-- ============================================================================= -->
  <!-- FINGERS -->
  <!-- RIGHT HAND due to which finger is number 0 -->
  <!-- for LEFT HAND switch the sign of the **offset_origin_y** and **finger_angle_r** parameters-->
  <!-- [LINK 0, 4, 8] -->
  <link name="hand_index_link_0">
    <visual>
      <geometry>
        <mesh filename="package://ros_thermal_grasp/data/allegro/link_0.0.STL"/>
      </geometry>
      <material name="Black"/>
    </visual>
    <collision>
      <geometry>
        <box size="0.0196 0.0275 0.0164"/>
      </geometry>
      <origin rpy="0 0 0" xyz="0 0 0.0082"/>
    </collision>
    <inertial>
      <mass value="0.0119"/>
      <origin rpy="0 0 0" xyz="0 0 0"/>
      <inertia ixx="1.01666658333e-06" ixy="0.0" ixz="0.0" iyy="6.47677333333e-07" iyz="0.0" izz="1.01666658333e-06"/>
    </inertial>
  </link>
  <gazebo reference="index_link_0">
    <material value="Gazebo/Black"/>
  </gazebo>
  <joint name="hand_index_joint_0" type="revolute">
    <axis xyz="0 0 1"/>
    <limit effort="15" lower="-0.59" upper="0.57" velocity="7"/>
    <parent link="hand_palm_link"/>
    <child link="hand_index_link_0"/>
    <origin rpy="-0.08726646255 0 0" xyz="0 0.0435 -0.001542"/>
    <dynamics damping="1" friction="0"/>
  </joint>
  <!-- [LINK 1, 5, 9] -->
  <link name="hand_index_link_1">
    <visual>
      <geometry>
        <mesh filename="package://ros_thermal_grasp/data/allegro/link_1.0.STL"/>
      </geometry>
      <material name="Black"/>
    </visual>
    <collision>
      <geometry>
        <box size="0.0196 0.0275 0.054"/>
      </geometry>
      <origin rpy="0 0 0" xyz="0 0 0.027"/>
    </collision>
    <inertial>
      <mass value="0.065"/>
      <origin rpy="0 0 0" xyz="0 0 0"/>
      <inertia ixx="7.95654166667e-05" ixy="1.7199e-05" ixz="8.75875e-06" iyy="2.47088833333e-05" iyz="2.413125e-05" izz="7.95654166667e-05"/>
    </inertial>
  </link>
  <gazebo reference="index_link_1">
    <material value="Gazebo/Black"/>
  </gazebo>
  <joint name="hand_index_joint_1" type="revolute">
    <limit effort="15" lower="-0.296" upper="1.71" velocity="7"/>
    <axis xyz="0 1 0"/>
    <parent link="hand_index_link_0"/>
    <child link="hand_index_link_1"/>
    <origin xyz="0 0 0.0164"/>
    <dynamics damping="1" friction="0"/>
  </joint>
  <!-- [LINK 2, 6, 10]-->
  <link name="hand_index_link_2">
    <visual>
      <geometry>
        <mesh filename="package://ros_thermal_grasp/data/allegro/link_2.0.STL"/>
      </geometry>
      <material name="Black"/>
    </visual>
    <collision>
      <geometry>
        <box size="0.0196 0.0275 0.0384"/>
      </geometry>
      <origin rpy="0 0 0" xyz="0 0 0.0192"/>
    </collision>
    <inertial>
      <mass value="0.0355"/>
      <origin rpy="0 0 0" xyz="0 0 0"/>
      <inertia ixx="2.63979183333e-05" ixy="6.67968e-06" ixz="4.783625e-06" iyy="1.34948516667e-05" iyz="9.372e-06" izz="2.63979183333e-05"/>
    </inertial>
  </link>
  <gazebo reference="index_link_2">
    <material value="Gazebo/Black"/>
  </gazebo>
  <joint name="hand_index_joint_2" type="revolute">
    <axis xyz="0 1 0"/>
    <limit effort="15" lower="-0.274" upper="1.809" velocity="7"/>
    <parent link="hand_index_link_1"/>
    <child link="hand_index_link_2"/>
    <origin xyz="0 0 0.054"/>
    <dynamics damping="1" friction="0"/>
  </joint>
  <!-- [LINK 3, 7, 11] -->
  <link name="hand_index_link_3">
    <visual>
      <geometry>
        <mesh filename="package://ros_thermal_grasp/data/allegro/link_3.0.STL"/>
      </geometry>
      <material name="Black"/>
    </visual>
    <collision>
      <geometry>
        <box size="0.0196 0.0275 0.0267"/>
      </geometry>
      <origin rpy="0 0 0" xyz="0 0 0.01335"/>
    </collision>
    <inertial>
      <mass value="0.0096"/>
      <origin rpy="0 0 0" xyz="0 0 0"/>
      <inertia ixx="4.701248e-06" ixy="1.255968e-06" ixz="1.2936e-06" iyy="3.649312e-06" iyz="1.7622e-06" izz="4.701248e-06"/>
    </inertial>
  </link>
  <gazebo reference="index_link_3">
    <material value="Gazebo/Black"/>
  </gazebo>
  <joint name="hand_index_joint_3" type="revolute">
    <axis xyz="0 1 0"/>
    <limit effort="15" lower="-0.327" upper="1.718" velocity="7"/>
    <parent link="hand_index_link_2"/>
    <child link="hand_index_link_3"/>
    <origin xyz="0 0 0.0384"/>
    <dynamics damping="10" friction="0"/>
  </joint>
  <!-- [FINGER TIP] -->
  <link name="hand_index_tip">
    <visual>
      <geometry>
        <mesh filename="package://ros_thermal_grasp/data/allegro/link_3.0_tip.STL"/>
      </geometry>
      <material name="White"/>
    </visual>
    <collision>
      <geometry>
        <sphere radius="0.012"/>
      </geometry>
    </collision>
    <inertial>
      <mass value="0.0168"/>
      <origin rpy="0 0 0" xyz="0 0 0"/>
      <inertia ixx="9.68e-07" ixy="0" ixz="0" iyy="9.68e-07" iyz="0" izz="9.68e-07"/>
    </inertial>
  </link>
  <joint name="hand_index_tip_joint" type="fixed">
    <parent link="hand_index_link_3"/>
    <child link="hand_index_tip"/>
    <origin rpy="0 0 0" xyz="0 0 0.0267"/>
  </joint>
  <!-- [LINK 0, 4, 8] -->
  <link name="hand_middle_link_0">
    <visual>
      <geometry>
        <mesh filename="package://ros_thermal_grasp/data/allegro/link_0.0.STL"/>
      </geometry>
      <material name="Black"/>
    </visual>
    <collision>
      <geometry>
        <box size="0.0196 0.0275 0.0164"/>
      </geometry>
      <origin rpy="0 0 0" xyz="0 0 0.0082"/>
    </collision>
    <inertial>
      <mass value="0.0119"/>
      <origin rpy="0 0 0" xyz="0 0 0"/>
      <inertia ixx="1.01666658333e-06" ixy="0.0" ixz="0.0" iyy="6.47677333333e-07" iyz="0.0" izz="1.01666658333e-06"/>
    </inertial>
  </link>
  <gazebo reference="middle_link_0">
    <material value="Gazebo/Black"/>
  </gazebo>
  <joint name="hand_middle_joint_0" type="revolute">
    <axis xyz="0 0 1"/>
    <limit effort="15" lower="-0.59" upper="0.57" velocity="7"/>
    <parent link="hand_palm_link"/>
    <child link="hand_middle_link_0"/>
    <origin rpy="0.0 0 0" xyz="0 0 0.0007"/>
    <dynamics damping="1" friction="0"/>
  </joint>
  <!-- [LINK 1, 5, 9] -->
  <link name="hand_middle_link_1">
    <visual>
      <geometry>
        <mesh filename="package://ros_thermal_grasp/data/allegro/link_1.0.STL"/>
      </geometry>
      <material name="Black"/>
    </visual>
    <collision>
      <geometry>
        <box size="0.0196 0.0275 0.054"/>
      </geometry>
      <origin rpy="0 0 0" xyz="0 0 0.027"/>
    </collision>
    <inertial>
      <mass value="0.065"/>
      <origin rpy="0 0 0" xyz="0 0 0"/>
      <inertia ixx="7.95654166667e-05" ixy="1.7199e-05" ixz="8.75875e-06" iyy="2.47088833333e-05" iyz="2.413125e-05" izz="7.95654166667e-05"/>
    </inertial>
  </link>
  <gazebo reference="middle_link_1">
    <material value="Gazebo/Black"/>
  </gazebo>
  <joint name="hand_middle_joint_1" type="revolute">
    <limit effort="15" lower="-0.296" upper="1.71" velocity="7"/>
    <axis xyz="0 1 0"/>
    <parent link="hand_middle_link_0"/>
    <child link="hand_middle_link_1"/>
    <origin xyz="0 0 0.0164"/>
    <dynamics damping="1" friction="0"/>
  </joint>
  <!-- [LINK 2, 6, 10]-->
  <link name="hand_middle_link_2">
    <visual>
      <geometry>
        <mesh filename="package://ros_thermal_grasp/data/allegro/link_2.0.STL"/>
      </geometry>
      <material name="Black"/>
    </visual>
    <collision>
      <geometry>
        <box size="0.0196 0.0275 0.0384"/>
      </geometry>
      <origin rpy="0 0 0" xyz="0 0 0.0192"/>
    </collision>
    <inertial>
      <mass value="0.0355"/>
      <origin rpy="0 0 0" xyz="0 0 0"/>
      <inertia ixx="2.63979183333e-05" ixy="6.67968e-06" ixz="4.783625e-06" iyy="1.34948516667e-05" iyz="9.372e-06" izz="2.63979183333e-05"/>
    </inertial>
  </link>
  <gazebo reference="middle_link_2">
    <material value="Gazebo/Black"/>
  </gazebo>
  <joint name="hand_middle_joint_2" type="revolute">
    <axis xyz="0 1 0"/>
    <limit effort="15" lower="-0.274" upper="1.809" velocity="7"/>
    <parent link="hand_middle_link_1"/>
    <child link="hand_middle_link_2"/>
    <origin xyz="0 0 0.054"/>
    <dynamics damping="1" friction="0"/>
  </joint>
  <!-- [LINK 3, 7, 11] -->
  <link name="hand_middle_link_3">
    <visual>
      <geometry>
        <mesh filename="package://ros_thermal_grasp/data/allegro/link_3.0.STL"/>
      </geometry>
      <material name="Black"/>
    </visual>
    <collision>
      <geometry>
        <box size="0.0196 0.0275 0.0267"/>
      </geometry>
      <origin rpy="0 0 0" xyz="0 0 0.01335"/>
    </collision>
    <inertial>
      <mass value="0.0096"/>
      <origin rpy="0 0 0" xyz="0 0 0"/>
      <inertia ixx="4.701248e-06" ixy="1.255968e-06" ixz="1.2936e-06" iyy="3.649312e-06" iyz="1.7622e-06" izz="4.701248e-06"/>
    </inertial>
  </link>
  <gazebo reference="middle_link_3">
    <material value="Gazebo/Black"/>
  </gazebo>
  <joint name="hand_middle_joint_3" type="revolute">
    <axis xyz="0 1 0"/>
    <limit effort="15" lower="-0.327" upper="1.718" velocity="7"/>
    <parent link="hand_middle_link_2"/>
    <child link="hand_middle_link_3"/>
    <origin xyz="0 0 0.0384"/>
    <dynamics damping="10" friction="0"/>
  </joint>
  <!-- [FINGER TIP] -->
  <link name="hand_middle_tip">
    <visual>
      <geometry>
        <mesh filename="package://ros_thermal_grasp/data/allegro/link_3.0_tip.STL"/>
      </geometry>
      <material name="White"/>
    </visual>
    <collision>
      <geometry>
        <sphere radius="0.012"/>
      </geometry>
    </collision>
    <inertial>
      <mass value="0.0168"/>
      <origin rpy="0 0 0" xyz="0 0 0"/>
      <inertia ixx="9.68e-07" ixy="0" ixz="0" iyy="9.68e-07" iyz="0" izz="9.68e-07"/>
    </inertial>
  </link>
  <joint name="hand_middle_tip_joint" type="fixed">
    <parent link="hand_middle_link_3"/>
    <child link="hand_middle_tip"/>
    <origin rpy="0 0 0" xyz="0 0 0.0267"/>
  </joint>
  <!-- [LINK 0, 4, 8] -->
  <link name="hand_ring_link_0">
    <visual>
      <geometry>
        <mesh filename="package://ros_thermal_grasp/data/allegro/link_0.0.STL"/>
      </geometry>
      <material name="Black"/>
    </visual>
    <collision>
      <geometry>
        <box size="0.0196 0.0275 0.0164"/>
      </geometry>
      <origin rpy="0 0 0" xyz="0 0 0.0082"/>
    </collision>
    <inertial>
      <mass value="0.0119"/>
      <origin rpy="0 0 0" xyz="0 0 0"/>
      <inertia ixx="1.01666658333e-06" ixy="0.0" ixz="0.0" iyy="6.47677333333e-07" iyz="0.0" izz="1.01666658333e-06"/>
    </inertial>
  </link>
  <gazebo reference="ring_link_0">
    <material value="Gazebo/Black"/>
  </gazebo>
  <joint name="hand_ring_joint_0" type="revolute">
    <axis xyz="0 0 1"/>
    <limit effort="15" lower="-0.59" upper="0.57" velocity="7"/>
    <parent link="hand_palm_link"/>
    <child link="hand_ring_link_0"/>
    <origin rpy="0.08726646255 0 0" xyz="0 -0.0435 -0.001542"/>
    <dynamics damping="1" friction="0"/>
  </joint>
  <!-- [LINK 1, 5, 9] -->
  <link name="hand_ring_link_1">
    <visual>
      <geometry>
        <mesh filename="package://ros_thermal_grasp/data/allegro/link_1.0.STL"/>
      </geometry>
      <material name="Black"/>
    </visual>
    <collision>
      <geometry>
        <box size="0.0196 0.0275 0.054"/>
      </geometry>
      <origin rpy="0 0 0" xyz="0 0 0.027"/>
    </collision>
    <inertial>
      <mass value="0.065"/>
      <origin rpy="0 0 0" xyz="0 0 0"/>
      <inertia ixx="7.95654166667e-05" ixy="1.7199e-05" ixz="8.75875e-06" iyy="2.47088833333e-05" iyz="2.413125e-05" izz="7.95654166667e-05"/>
    </inertial>
  </link>
  <gazebo reference="ring_link_1">
    <material value="Gazebo/Black"/>
  </gazebo>
  <joint name="hand_ring_joint_1" type="revolute">
    <limit effort="15" lower="-0.296" upper="1.71" velocity="7"/>
    <axis xyz="0 1 0"/>
    <parent link="hand_ring_link_0"/>
    <child link="hand_ring_link_1"/>
    <origin xyz="0 0 0.0164"/>
    <dynamics damping="1" friction="0"/>
  </joint>
  <!-- [LINK 2, 6, 10]-->
  <link name="hand_ring_link_2">
    <visual>
      <geometry>
        <mesh filename="package://ros_thermal_grasp/data/allegro/link_2.0.STL"/>
      </geometry>
      <material name="Black"/>
    </visual>
    <collision>
      <geometry>
        <box size="0.0196 0.0275 0.0384"/>
      </geometry>
      <origin rpy="0 0 0" xyz="0 0 0.0192"/>
    </collision>
    <inertial>
      <mass value="0.0355"/>
      <origin rpy="0 0 0" xyz="0 0 0"/>
      <inertia ixx="2.63979183333e-05" ixy="6.67968e-06" ixz="4.783625e-06" iyy="1.34948516667e-05" iyz="9.372e-06" izz="2.63979183333e-05"/>
    </inertial>
  </link>
  <gazebo reference="ring_link_2">
    <material value="Gazebo/Black"/>
  </gazebo>
  <joint name="hand_ring_joint_2" type="revolute">
    <axis xyz="0 1 0"/>
    <limit effort="15" lower="-0.274" upper="1.809" velocity="7"/>
    <parent link="hand_ring_link_1"/>
    <child link="hand_ring_link_2"/>
    <origin xyz="0 0 0.054"/>
    <dynamics damping="1" friction="0"/>
  </joint>
  <!-- [LINK 3, 7, 11] -->
  <link name="hand_ring_link_3">
    <visual>
      <geometry>
        <mesh filename="package://ros_thermal_grasp/data/allegro/link_3.0.STL"/>
      </geometry>
      <material name="Black"/>
    </visual>
    <collision>
      <geometry>
        <box size="0.0196 0.0275 0.0267"/>
      </geometry>
      <origin rpy="0 0 0" xyz="0 0 0.01335"/>
    </collision>
    <inertial>
      <mass value="0.0096"/>
      <origin rpy="0 0 0" xyz="0 0 0"/>
      <inertia ixx="4.701248e-06" ixy="1.255968e-06" ixz="1.2936e-06" iyy="3.649312e-06" iyz="1.7622e-06" izz="4.701248e-06"/>
    </inertial>
  </link>
  <gazebo reference="ring_link_3">
    <material value="Gazebo/Black"/>
  </gazebo>
  <joint name="hand_ring_joint_3" type="revolute">
    <axis xyz="0 1 0"/>
    <limit effort="15" lower="-0.327" upper="1.718" velocity="7"/>
    <parent link="hand_ring_link_2"/>
    <child link="hand_ring_link_3"/>
    <origin xyz="0 0 0.0384"/>
    <dynamics damping="10" friction="0"/>
  </joint>
  <!-- [FINGER TIP] -->
  <link name="hand_ring_tip">
    <visual>
      <geometry>
        <mesh filename="package://ros_thermal_grasp/data/allegro/link_3.0_tip.STL"/>
      </geometry>
      <material name="White"/>
    </visual>
    <collision>
      <geometry>
        <sphere radius="0.012"/>
      </geometry>
    </collision>
    <inertial>
      <mass value="0.0168"/>
      <origin rpy="0 0 0" xyz="0 0 0"/>
      <inertia ixx="9.68e-07" ixy="0" ixz="0" iyy="9.68e-07" iyz="0" izz="9.68e-07"/>
    </inertial>
  </link>
  <joint name="hand_ring_tip_joint" type="fixed">
    <parent link="hand_ring_link_3"/>
    <child link="hand_ring_tip"/>
    <origin rpy="0 0 0" xyz="0 0 0.0267"/>
  </joint>
  <!-- THUMB -->
  <!-- [LINK 12] -->
  <link name="hand_thumb_link_0">
    <visual>
      <geometry>
        <mesh filename="package://ros_thermal_grasp/data/allegro/link_12.0_right.STL"/>
      </geometry>
      <material name="Black"/>
    </visual>
    <collision>
      <geometry>
        <box size="0.0358 0.034 0.0455"/>
      </geometry>
      <origin rpy="0 0 0" xyz="-0.0179 0.009 0.0145"/>
    </collision>
    <inertial>
      <mass value="0.0176"/>
      <origin rpy="0 0 0" xyz="0 0 0"/>
      <inertia ixx="1.89273333333e-5" ixy="7.16716e-06" ixz="5.35568e-06" iyy="1.43008213333e-05" iyz="6.8068e-06" izz="1.89273333333e-05"/>
    </inertial>
  </link>
  <gazebo reference="thumb_link_0">
    <material value="Gazebo/Black"/>
  </gazebo>
  <joint name="hand_thumb_joint_0" type="revolute">
    <axis xyz="-1 0 0"/>
    <limit effort="15" lower="0.363" upper="1.62" velocity="7"/>
    <parent link="hand_palm_link"/>
    <child link="hand_thumb_link_0"/>
    <!--origin rpy="0 -1.65806278845 -1.5707963259" xyz="-0.0182 0.019333 -0.045987"/-->
    <origin rpy="0 -1.65806278845 -1.417963259" xyz="-0.0182 0.022333 -0.045987"/>
    <dynamics damping="1" friction="0"/>
  </joint>
  <!-- [LINK 13] -->
  <link name="hand_thumb_link_1">
    <visual>
      <geometry>
        <mesh filename="package://ros_thermal_grasp/data/allegro/link_13.0.STL"/>
      </geometry>
      <material name="Black"/>
    </visual>
    <collision>
      <geometry>
        <box size="0.0196 0.0275 0.0177"/>
      </geometry>
      <origin rpy="0 0 0" xyz="0 0 0.00885"/>
    </collision>
    <inertial>
      <mass value="0.0119"/>
      <origin rpy="0 0 0" xyz="0 0 0"/>
      <inertia ixx="4.24250866667e-06" ixy="1.032087e-06" ixz="1.603525e-06" iyy="4.52362633333e-06" iyz="1.44808125e-06" izz="4.24250866667e-06"/>
    </inertial>
  </link>
  <gazebo reference="thumb_link_1">
    <material value="Gazebo/Black"/>
  </gazebo>
  <joint name="hand_thumb_joint_1" type="revolute">
    <axis xyz="0 0 1"/>
    <limit effort="15" lower="-0.205" upper="1.263" velocity="7"/>
    <parent link="hand_thumb_link_0"/>
    <child link="hand_thumb_link_1"/>
    <origin xyz="-0.027 0.005 0.0399"/>
    <dynamics damping="1" friction="0"/>
  </joint>
  <!-- [LINK 14] -->
  <link name="hand_thumb_link_2">
    <visual>
      <geometry>
        <mesh filename="package://ros_thermal_grasp/data/allegro/link_14.0.STL"/>
      </geometry>
      <material name="Black">
        </material>
    </visual>
    <collision>
      <geometry>
        <box size="0.0196 0.0275 0.0514"/>
      </geometry>
      <origin rpy="0 0 0" xyz="0 0 0.0257"/>
    </collision>
    <inertial>
      <mass value="0.038"/>
      <origin rpy="0 0 0" xyz="0 0 0"/>
      <inertia ixx="4.30439933333e-05" ixy="9.57068e-06" ixz="5.1205e-06" iyy="1.44451933333e-05" iyz="1.342825e-05" izz="4.30439933333e-05"/>
    </inertial>
  </link>
  <gazebo reference="thumb_link_2">
    <material value="Gazebo/Black"/>
  </gazebo>
  <joint name="hand_thumb_joint_2" type="revolute">
    <axis xyz="0 1 0"/>
    <limit effort="15" lower="-0.289" upper="1.744" velocity="7"/>
    <parent link="hand_thumb_link_1"/>
    <child link="hand_thumb_link_2"/>
    <origin xyz="0 0 0.0177"/>
    <dynamics damping="1" friction="0"/>
  </joint>
  <!-- [LINK 15] -->
  <link name="hand_thumb_link_3">
    <visual>
      <geometry>
        <mesh filename="package://ros_thermal_grasp/data/allegro/link_15.0.STL"/>
      </geometry>
      <material name="Black">
        </material>
    </visual>
    <collision>
      <geometry>
        <box size="0.0196 0.0275 0.0423"/>
      </geometry>
      <origin rpy="0 0 0" xyz="0 0 0.02115"/>
    </collision>
    <inertial>
      <mass value="0.0388"/>
      <origin rpy="0 0 0" xyz="0 0 0"/>
      <inertia ixx="3.29223173333e-05" ixy="8.042076e-06" ixz="5.2283e-06" iyy="1.47493026667e-5" iyz="1.1283525e-5" izz="3.29223173333e-05"/>
    </inertial>
  </link>
  <gazebo reference="thumb_link_3">
    <material value="Gazebo/Black"/>
  </gazebo>
  <joint name="hand_thumb_joint_3" type="revolute">
    <axis xyz="0 1 0"/>
    <limit effort="15" lower="-0.262" upper="1.819" velocity="7"/>
    <parent link="hand_thumb_link_2"/>
    <child link="hand_thumb_link_3"/>
    <origin xyz="0 0 0.0514"/>
    <dynamics damping="1" friction="0"/>
  </joint>
  <!-- [FINGER TIP] -->
  <link name="hand_thumb_tip">
    <visual>
      <geometry>
        <mesh filename="package://ros_thermal_grasp/data/allegro/link_15.0_tip.STL"/>
      </geometry>
      <material name="White"/>
    </visual>
    <collision>
      <geometry>
        <sphere radius="0.012"/>
      </geometry>
      <origin rpy="0 0 0" xyz="0 0 0"/>
    </collision>
    <inertial>
      <mass value="0.0168"/>
      <origin rpy="0 0 0" xyz="0 0 0"/>
      <inertia ixx="9.68e-07" ixy="0" ixz="0" iyy="9.68e-07" iyz="0" izz="9.68e-07"/>
    </inertial>
  </link>
  <joint name="hand_thumb_tip_joint" type="fixed">
    <parent link="hand_thumb_link_3"/>
    <child link="hand_thumb_tip"/>
    <origin rpy="0 0 0" xyz="0 0 0.0423"/>
  </joint>
  <!-- ============================================================================= -->
  <!-- THUMB MACRO -->
  <!-- END THUMB MACRO -->
  <!-- THREE FINGER MACRO -->
  <!-- [[END]] THREE FINGER MACRO -->
  <joint name="robot_tool0-base_link" type="fixed">
    <origin rpy="0 0 3.14159265359" xyz="0 0 0.1"/>
    <parent link="robot_tool0"/>
    <child link="hand_palm_link"/>
  </joint>
</robot>
